<?xml version="1.0" encoding="utf-8"?>
<!-- This URDF was automatically created by SolidWorks to URDF Exporter! Originally created by Stephen Brawner (brawner@gmail.com) 
     Commit Version: 1.5.1-0-g916b5db  Build Version: 1.5.7152.31018
     For more information, please see http://wiki.ros.org/sw_urdf_exporter -->
<robot
  name="Phantom">
  <link
    name="base_link">
    <inertial>
      <origin
        xyz="0 0.024688 0"
        rpy="0 0 0" />
      <mass
        value="0.50654" />
      <inertia
        ixx="0.0017719"
        ixy="1.6105E-07"
        ixz="-8.064E-07"
        iyy="0.0025693"
        iyz="-4.4001E-05"
        izz="0.0011851" />
    </inertial>
    <visual>
      <origin
        xyz="0 0 0"
        rpy="0 0 0" />
      <geometry>
        <mesh
          filename="package://Phantom/meshes/base_link.STL" />
      </geometry>
      <material
        name="">
        <color
          rgba="0.75294 0.75294 0.75294 1" />
      </material>
    </visual>
    <collision>
      <origin
        xyz="0 0 0"
        rpy="0 0 0" />
      <geometry>
        <mesh
          filename="package://Phantom/meshes/base_link.STL" />
      </geometry>
    </collision>
  </link>
  <link
    name="FL_Motor_2">
    <inertial>
      <origin
        xyz="9.012E-07 0.025811 0.00021934"
        rpy="0 0 0" />
      <mass
        value="0.038306" />
      <inertia
        ixx="8.8892E-06"
        ixy="-8.9901E-11"
        ixz="2.9471E-11"
        iyy="5.0029E-06"
        iyz="-6.1827E-09"
        izz="7.6904E-06" />
    </inertial>
    <visual>
      <origin
        xyz="0 0 0"
        rpy="0 0 0" />
      <geometry>
        <mesh
          filename="package://Phantom/meshes/FL_Motor_2.STL" />
      </geometry>
      <material
        name="">
        <color
          rgba="0.75294 0.75294 0.75294 1" />
      </material>
    </visual>
    <collision>
      <origin
        xyz="0 0 0"
        rpy="0 0 0" />
      <geometry>
        <mesh
          filename="package://Phantom/meshes/FL_Motor_2.STL" />
      </geometry>
    </collision>
  </link>
  <joint
    name="FL_Motor_1"
    type="revolute">
    <origin
      xyz="0.06 -0.106 0.0396"
      rpy="0 -1.5708 0" />
    <parent
      link="base_link" />
    <child
      link="FL_Motor_2" />
    <axis
      xyz="0 1 0" />
    <limit
      lower="-1.57"
      upper="1.57"
      effort="1.6"
      velocity="6.55" />
  </joint>
  <link
    name="FL_Upper_Leg">
    <inertial>
      <origin
        xyz="0.0524807185071959 -0.0149043297355802 0.0456863302589959"
        rpy="0 0 0" />
      <mass
        value="0.109481468712912" />
      <inertia
        ixx="0.000298068457356141"
        ixy="4.60867940853905E-05"
        ixz="-3.85596458595883E-06"
        iyy="0.000125014667087998"
        iyz="7.78430032608335E-05"
        izz="0.000265806457751462" />
    </inertial>
    <visual>
      <origin
        xyz="0 0 0"
        rpy="0 0 0" />
      <geometry>
        <mesh
          filename="package://Phantom/meshes/FL_Upper_Leg.STL" />
      </geometry>
      <material
        name="">
        <color
          rgba="0.752941176470588 0.752941176470588 0.752941176470588 1" />
      </material>
    </visual>
    <collision>
      <origin
        xyz="0 0 0"
        rpy="0 0 0" />
      <geometry>
        <mesh
          filename="package://Phantom/meshes/FL_Upper_Leg.STL" />
      </geometry>
    </collision>
  </link>
  <joint
    name="FL_Motor_2"
    type="revolute">
    <origin
      xyz="0 0.0396 0"
      rpy="0.40064 -0.90551 -1.6929" />
    <parent
      link="FL_Motor_2" />
    <child
      link="FL_Upper_Leg" />
    <axis
      xyz="0.78674 0.24074 0.5684" />
    <limit
      lower="-1.57"
      upper="1.57"
      effort="1.6"
      velocity="6.55" />
  </joint>
  <link
    name="FL_Lower_Leg">
    <inertial>
      <origin
        xyz="0.0261394692100626 -0.0573467070566691 0.0104588260023856"
        rpy="0 0 0" />
      <mass
        value="0.0232960712336725" />
      <inertia
        ixx="1.52233611319829E-05"
        ixy="1.16167374959236E-06"
        ixz="-2.08623801817281E-07"
        iyy="1.7871148944761E-06"
        iyz="2.42971146104759E-06"
        izz="1.50217948778946E-05" />
    </inertial>
    <visual>
      <origin
        xyz="0 0 0"
        rpy="0 0 0" />
      <geometry>
        <mesh
          filename="package://Phantom/meshes/FL_Lower_Leg.STL" />
      </geometry>
      <material
        name="">
        <color
          rgba="0.752941176470588 0.752941176470588 0.752941176470588 1" />
      </material>
    </visual>
    <collision>
      <origin
        xyz="0 0 0"
        rpy="0 0 0" />
      <geometry>
        <mesh
          filename="package://Phantom/meshes/FL_Lower_Leg.STL" />
      </geometry>
    </collision>
  </link>
  <joint
    name="FL_Motor_3"
    type="revolute">
    <origin
      xyz="0.054695 -0.15377 0.082305"
      rpy="-1.778 -0.67517 0.31496" />
    <parent
      link="FL_Upper_Leg" />
    <child
      link="FL_Lower_Leg" />
    <axis
      xyz="0.9974 0.072007 0" />
    <limit
      lower="-1"
      upper="1"
      effort="1.6"
      velocity="6.55" />
  </joint>
  <link
    name="FL_Foot">
    <inertial>
      <origin
        xyz="-1.43877699615436E-08 0.00686484405727211 -2.77555756156289E-17"
        rpy="0 0 0" />
      <mass
        value="0.00129233386377228" />
      <inertia
        ixx="2.80098247181732E-08"
        ixy="-8.19106279544417E-14"
        ixz="-2.31601914376966E-23"
        iyy="3.46211587846662E-08"
        iyz="6.90000589927413E-24"
        izz="2.80108403065588E-08" />
    </inertial>
    <visual>
      <origin
        xyz="0 0 0"
        rpy="0 0 0" />
      <geometry>
        <mesh
          filename="package://Phantom/meshes/FL_Foot.STL" />
      </geometry>
      <material
        name="">
        <color
          rgba="0.792156862745098 0.819607843137255 0.933333333333333 1" />
      </material>
    </visual>
    <collision>
      <origin
        xyz="0 0 0"
        rpy="0 0 0" />
      <geometry>
        <mesh
          filename="package://Phantom/meshes/FL_Foot.STL" />
      </geometry>
    </collision>
  </link>
  <joint
    name="FL_Foot_Joint"
    type="fixed">
    <origin
      xyz="0.033045 -0.15002 0.026918"
      rpy="0.42172 1.1307 -2.6839" />
    <parent
      link="FL_Lower_Leg" />
    <child
      link="FL_Foot" />
    <axis
      xyz="0 0 0" />
  </joint>
  <link
    name="FR_Motor_2">
    <inertial>
      <origin
        xyz="9.01196952313166E-07 0.0258106475147315 0.000219339271449077"
        rpy="0 0 0" />
      <mass
        value="0.0383058924829272" />
      <inertia
        ixx="8.8892013763251E-06"
        ixy="-8.9900828311236E-11"
        ixz="2.94712337558651E-11"
        iyy="5.00287526627567E-06"
        iyz="-6.18267002550534E-09"
        izz="7.69036723458956E-06" />
    </inertial>
    <visual>
      <origin
        xyz="0 0 0"
        rpy="0 0 0" />
      <geometry>
        <mesh
          filename="package://Phantom/meshes/FR_Motor_2.STL" />
      </geometry>
      <material
        name="">
        <color
          rgba="0.752941176470588 0.752941176470588 0.752941176470588 1" />
      </material>
    </visual>
    <collision>
      <origin
        xyz="0 0 0"
        rpy="0 0 0" />
      <geometry>
        <mesh
          filename="package://Phantom/meshes/FR_Motor_2.STL" />
      </geometry>
    </collision>
  </link>
  <joint
    name="FR_Motor_1"
    type="revolute">
    <origin
      xyz="-0.06 -0.106 0.0396"
      rpy="3.1416 1.5708 0" />
    <parent
      link="base_link" />
    <child
      link="FR_Motor_2" />
    <axis
      xyz="0 1 0" />
    <limit
      lower="-1.57"
      upper="1.57"
      effort="1.6"
      velocity="6.55" />
  </joint>
  <link
    name="FR_Upper_Leg">
    <inertial>
      <origin
        xyz="0.052480718507193 -0.0149043297355734 0.0456863302590011"
        rpy="0 0 0" />
      <mass
        value="0.109481468712911" />
      <inertia
        ixx="0.000298068457356142"
        ixy="4.60867940853844E-05"
        ixz="-3.8559645859582E-06"
        iyy="0.000125014667088"
        iyz="7.78430032608387E-05"
        izz="0.000265806457751455" />
    </inertial>
    <visual>
      <origin
        xyz="0 0 0"
        rpy="0 0 0" />
      <geometry>
        <mesh
          filename="package://Phantom/meshes/FR_Upper_Leg.STL" />
      </geometry>
      <material
        name="">
        <color
          rgba="0.752941176470588 0.752941176470588 0.752941176470588 1" />
      </material>
    </visual>
    <collision>
      <origin
        xyz="0 0 0"
        rpy="0 0 0" />
      <geometry>
        <mesh
          filename="package://Phantom/meshes/FR_Upper_Leg.STL" />
      </geometry>
    </collision>
  </link>
  <joint
    name="FR_Motor_2"
    type="revolute">
    <origin
      xyz="0 0.0396 0"
      rpy="0.40064 -0.90551 1.4487" />
    <parent
      link="FR_Motor_2" />
    <child
      link="FR_Upper_Leg" />
    <axis
      xyz="0.78674 0.24074 0.5684" />
    <limit
      lower="-1.57"
      upper="1.57"
      effort="1.6"
      velocity="6.55" />
  </joint>
  <link
    name="FR_Lower_Leg">
    <inertial>
      <origin
        xyz="0.0261394692100617 -0.0573467070566894 0.0104588260024016"
        rpy="0 0 0" />
      <mass
        value="0.0232960712337112" />
      <inertia
        ixx="1.52233611319807E-05"
        ixy="1.1616737495922E-06"
        ixz="-2.08623801817473E-07"
        iyy="1.78711489447468E-06"
        iyz="2.42971146104814E-06"
        izz="1.50217948778951E-05" />
    </inertial>
    <visual>
      <origin
        xyz="0 0 0"
        rpy="0 0 0" />
      <geometry>
        <mesh
          filename="package://Phantom/meshes/FR_Lower_Leg.STL" />
      </geometry>
      <material
        name="">
        <color
          rgba="0.752941176470588 0.752941176470588 0.752941176470588 1" />
      </material>
    </visual>
    <collision>
      <origin
        xyz="0 0 0"
        rpy="0 0 0" />
      <geometry>
        <mesh
          filename="package://Phantom/meshes/FR_Lower_Leg.STL" />
      </geometry>
    </collision>
  </link>
  <joint
    name="FR_Motor_3"
    type="revolute">
    <origin
      xyz="0.054695 -0.15377 0.082305"
      rpy="1.3831 -0.53381 0.28062" />
    <parent
      link="FR_Upper_Leg" />
    <child
      link="FR_Lower_Leg" />
    <axis
      xyz="0.9974 0.072007 0" />
    <limit
      lower="-1"
      upper="1"
      effort="1.6"
      velocity="6.55" />
  </joint>
  <link
    name="FR_Foot">
    <inertial>
      <origin
        xyz="-1.43877682406979E-08 0.00686484405727189 -2.91433543964104E-15"
        rpy="0 0 0" />
      <mass
        value="0.00129233386377229" />
      <inertia
        ixx="2.80098247181733E-08"
        ixy="-8.1910627847285E-14"
        ixz="2.27474668452083E-24"
        iyy="3.46211587846663E-08"
        iyz="8.41167116402596E-24"
        izz="2.80108403065589E-08" />
    </inertial>
    <visual>
      <origin
        xyz="0 0 0"
        rpy="0 0 0" />
      <geometry>
        <mesh
          filename="package://Phantom/meshes/FR_Foot.STL" />
      </geometry>
      <material
        name="">
        <color
          rgba="0.792156862745098 0.819607843137255 0.933333333333333 1" />
      </material>
    </visual>
    <collision>
      <origin
        xyz="0 0 0"
        rpy="0 0 0" />
      <geometry>
        <mesh
          filename="package://Phantom/meshes/FR_Foot.STL" />
      </geometry>
    </collision>
  </link>
  <joint
    name="FR_Foot_Joint"
    type="fixed">
    <origin
      xyz="0.033045 -0.15002 0.026918"
      rpy="2.9657 0.081336 0.057634" />
    <parent
      link="FR_Lower_Leg" />
    <child
      link="FR_Foot" />
    <axis
      xyz="0 0 0" />
  </joint>
  <link
    name="BL_Motor_2">
    <inertial>
      <origin
        xyz="9.01196952167449E-07 0.0258106475147312 0.000219339271229357"
        rpy="0 0 0" />
      <mass
        value="0.0383058924829273" />
      <inertia
        ixx="8.88920137632515E-06"
        ixy="-8.99008282886945E-11"
        ixz="2.94712337531726E-11"
        iyy="5.00287526627569E-06"
        iyz="-6.1826700255098E-09"
        izz="7.69036723458962E-06" />
    </inertial>
    <visual>
      <origin
        xyz="0 0 0"
        rpy="0 0 0" />
      <geometry>
        <mesh
          filename="package://Phantom/meshes/BL_Motor_2.STL" />
      </geometry>
      <material
        name="">
        <color
          rgba="0.752941176470588 0.752941176470588 0.752941176470588 1" />
      </material>
    </visual>
    <collision>
      <origin
        xyz="0 0 0"
        rpy="0 0 0" />
      <geometry>
        <mesh
          filename="package://Phantom/meshes/BL_Motor_2.STL" />
      </geometry>
    </collision>
  </link>
  <joint
    name="BL_Motor_1"
    type="revolute">
    <origin
      xyz="0.06 0.106 0.0396"
      rpy="0 1.5708 0" />
    <parent
      link="base_link" />
    <child
      link="BL_Motor_2" />
    <axis
      xyz="0 1 0" />
    <limit
      lower="-1.57"
      upper="1.57"
      effort="1.6"
      velocity="6.55" />
  </joint>
  <link
    name="BL_Upper_Leg">
    <inertial>
      <origin
        xyz="0.0524807185070219 -0.014904329735632 0.0456863302588721"
        rpy="0 0 0" />
      <mass
        value="0.109481468712912" />
      <inertia
        ixx="0.000298068457356145"
        ixy="4.60867940853866E-05"
        ixz="-3.8559645859584E-06"
        iyy="0.000125014667088"
        iyz="7.78430032608382E-05"
        izz="0.000265806457751459" />
    </inertial>
    <visual>
      <origin
        xyz="0 0 0"
        rpy="0 0 0" />
      <geometry>
        <mesh
          filename="package://Phantom/meshes/BL_Upper_Leg.STL" />
      </geometry>
      <material
        name="">
        <color
          rgba="0.752941176470588 0.752941176470588 0.752941176470588 1" />
      </material>
    </visual>
    <collision>
      <origin
        xyz="0 0 0"
        rpy="0 0 0" />
      <geometry>
        <mesh
          filename="package://Phantom/meshes/BL_Upper_Leg.STL" />
      </geometry>
    </collision>
  </link>
  <joint
    name="BL_Motor_2"
    type="revolute">
    <origin
      xyz="0 0.0396 0"
      rpy="0.40064 -0.90551 1.4487" />
    <parent
      link="BL_Motor_2" />
    <child
      link="BL_Upper_Leg" />
    <axis
      xyz="0.78674 0.24074 0.5684" />
    <limit
      lower="-1.57"
      upper="1.57"
      effort="1.6"
      velocity="6.55" />
  </joint>
  <link
    name="BL_Lower_Leg">
    <inertial>
      <origin
        xyz="0.0261394692100616 -0.0573467070566771 0.010458826002389"
        rpy="0 0 0" />
      <mass
        value="0.0232960712336856" />
      <inertia
        ixx="1.52233611319842E-05"
        ixy="1.16167374959205E-06"
        ixz="-2.08623801817332E-07"
        iyy="1.78711489447804E-06"
        iyz="2.42971146104767E-06"
        izz="1.50217948778954E-05" />
    </inertial>
    <visual>
      <origin
        xyz="0 0 0"
        rpy="0 0 0" />
      <geometry>
        <mesh
          filename="package://Phantom/meshes/BL_Lower_Leg.STL" />
      </geometry>
      <material
        name="">
        <color
          rgba="0.752941176470588 0.752941176470588 0.752941176470588 1" />
      </material>
    </visual>
    <collision>
      <origin
        xyz="0 0 0"
        rpy="0 0 0" />
      <geometry>
        <mesh
          filename="package://Phantom/meshes/BL_Lower_Leg.STL" />
      </geometry>
    </collision>
  </link>
  <joint
    name="BL_Motor_3"
    type="revolute">
    <origin
      xyz="0.054695 -0.15377 0.082305"
      rpy="-1.778 -0.67517 0.31496" />
    <parent
      link="BL_Upper_Leg" />
    <child
      link="BL_Lower_Leg" />
    <axis
      xyz="0.9974 0.072007 0" />
    <limit
      lower="-1"
      upper="1"
      effort="1.6"
      velocity="6.55" />
  </joint>
  <link
    name="BL_Foot">
    <inertial>
      <origin
        xyz="-1.43877698921546E-08 0.00686484405727179 2.77555756156289E-17"
        rpy="0 0 0" />
      <mass
        value="0.00129233386377229" />
      <inertia
        ixx="2.80098247181732E-08"
        ixy="-8.19106278465532E-14"
        ixz="-4.13579763320867E-24"
        iyy="3.46211587846662E-08"
        iyz="-4.48891407388988E-24"
        izz="2.80108403065589E-08" />
    </inertial>
    <visual>
      <origin
        xyz="0 0 0"
        rpy="0 0 0" />
      <geometry>
        <mesh
          filename="package://Phantom/meshes/BL_Foot.STL" />
      </geometry>
      <material
        name="">
        <color
          rgba="0.792156862745098 0.819607843137255 0.933333333333333 1" />
      </material>
    </visual>
    <collision>
      <origin
        xyz="0 0 0"
        rpy="0 0 0" />
      <geometry>
        <mesh
          filename="package://Phantom/meshes/BL_Foot.STL" />
      </geometry>
    </collision>
  </link>
  <joint
    name="BL_Foot_Joint"
    type="fixed">
    <origin
      xyz="0.033045 -0.15002 0.026918"
      rpy="0.44233 1.1512 -2.6613" />
    <parent
      link="BL_Lower_Leg" />
    <child
      link="BL_Foot" />
    <axis
      xyz="0 1 0" />
  </joint>
  <link
    name="BR_Motor_2">
    <inertial>
      <origin
        xyz="9.01196953048689E-07 0.0258106475147303 0.000219339271668104"
        rpy="0 0 0" />
      <mass
        value="0.0383058924829252" />
      <inertia
        ixx="8.88920137632514E-06"
        ixy="-8.9900828336558E-11"
        ixz="2.94712337510042E-11"
        iyy="5.00287526627568E-06"
        iyz="-6.18267002550552E-09"
        izz="7.69036723458959E-06" />
    </inertial>
    <visual>
      <origin
        xyz="0 0 0"
        rpy="0 0 0" />
      <geometry>
        <mesh
          filename="package://Phantom/meshes/BR_Motor_2.STL" />
      </geometry>
      <material
        name="">
        <color
          rgba="0.752941176470588 0.752941176470588 0.752941176470588 1" />
      </material>
    </visual>
    <collision>
      <origin
        xyz="0 0 0"
        rpy="0 0 0" />
      <geometry>
        <mesh
          filename="package://Phantom/meshes/BR_Motor_2.STL" />
      </geometry>
    </collision>
  </link>
  <joint
    name="BR_Motor_1"
    type="revolute">
    <origin
      xyz="-0.06 0.106 0.0396"
      rpy="3.1416 -1.5708 0" />
    <parent
      link="base_link" />
    <child
      link="BR_Motor_2" />
    <axis
      xyz="0 1 0" />
    <limit
      lower="-1.57"
      upper="1.57"
      effort="1.6"
      velocity="6.55" />
  </joint>
  <link
    name="BR_Upper_Leg">
    <inertial>
      <origin
        xyz="0.0524807185073673 -0.0149043297355264 0.0456863302591222"
        rpy="0 0 0" />
      <mass
        value="0.109481468712911" />
      <inertia
        ixx="0.00029806845735614"
        ixy="4.60867940853841E-05"
        ixz="-3.85596458595776E-06"
        iyy="0.000125014667087999"
        iyz="7.78430032608385E-05"
        izz="0.000265806457751453" />
    </inertial>
    <visual>
      <origin
        xyz="0 0 0"
        rpy="0 0 0" />
      <geometry>
        <mesh
          filename="package://Phantom/meshes/BR_Upper_Leg.STL" />
      </geometry>
      <material
        name="">
        <color
          rgba="0.752941176470588 0.752941176470588 0.752941176470588 1" />
      </material>
    </visual>
    <collision>
      <origin
        xyz="0 0 0"
        rpy="0 0 0" />
      <geometry>
        <mesh
          filename="package://Phantom/meshes/BR_Upper_Leg.STL" />
      </geometry>
    </collision>
  </link>
  <joint
    name="BR_Motor_2"
    type="revolute">
    <origin
      xyz="0 0.0396 0"
      rpy="0.40064 -0.90551 -1.6929" />
    <parent
      link="BR_Motor_2" />
    <child
      link="BR_Upper_Leg" />
    <axis
      xyz="0.78674 0.24074 0.5684" />
    <limit
      lower="-1.57"
      upper="1.57"
      effort="1.6"
      velocity="6.55" />
  </joint>
  <link
    name="BR_Lower_Leg">
    <inertial>
      <origin
        xyz="0.0261394692100596 -0.0573467070566696 0.0104588260023861"
        rpy="0 0 0" />
      <mass
        value="0.0232960712336743" />
      <inertia
        ixx="1.52233611319828E-05"
        ixy="1.1616737495921E-06"
        ixz="-2.08623801817723E-07"
        iyy="1.7871148944754E-06"
        iyz="2.42971146104731E-06"
        izz="1.50217948778944E-05" />
    </inertial>
    <visual>
      <origin
        xyz="0 0 0"
        rpy="0 0 0" />
      <geometry>
        <mesh
          filename="package://Phantom/meshes/BR_Lower_Leg.STL" />
      </geometry>
      <material
        name="">
        <color
          rgba="0.752941176470588 0.752941176470588 0.752941176470588 1" />
      </material>
    </visual>
    <collision>
      <origin
        xyz="0 0 0"
        rpy="0 0 0" />
      <geometry>
        <mesh
          filename="package://Phantom/meshes/BR_Lower_Leg.STL" />
      </geometry>
    </collision>
  </link>
  <joint
    name="BR_Motor_3"
    type="revolute">
    <origin
      xyz="0.054695 -0.15377 0.082305"
      rpy="1.3831 -0.53381 0.28062" />
    <parent
      link="BR_Upper_Leg" />
    <child
      link="BR_Lower_Leg" />
    <axis
      xyz="0.9974 0.072007 0" />
    <limit
      lower="-1"
      upper="1"
      effort="1.6"
      velocity="6.55" />
  </joint>
  <link
    name="BR_Foot">
    <inertial>
      <origin
        xyz="-1.43877705721662E-08 0.00686484405727178 4.44089209850063E-16"
        rpy="0 0 0" />
      <mass
        value="0.00129233386377228" />
      <inertia
        ixx="2.80098247181731E-08"
        ixy="-8.19106279262494E-14"
        ixz="-2.89444080637953E-24"
        iyy="3.46211587846661E-08"
        iyz="6.23490702340783E-23"
        izz="2.80108403065587E-08" />
    </inertial>
    <visual>
      <origin
        xyz="0 0 0"
        rpy="0 0 0" />
      <geometry>
        <mesh
          filename="package://Phantom/meshes/BR_Foot.STL" />
      </geometry>
      <material
        name="">
        <color
          rgba="0.792156862745098 0.819607843137255 0.933333333333333 1" />
      </material>
    </visual>
    <collision>
      <origin
        xyz="0 0 0"
        rpy="0 0 0" />
      <geometry>
        <mesh
          filename="package://Phantom/meshes/BR_Foot.STL" />
      </geometry>
    </collision>
  </link>
  <joint
    name="BR_Foot_Joint"
    type="fixed">
    <origin
      xyz="0.033045 -0.15002 0.026918"
      rpy="0.8796 -1.3425 2.347" />
    <parent
      link="BR_Lower_Leg" />
    <child
      link="BR_Foot" />
    <axis
      xyz="0 1 0" />
  </joint>
</robot>