<?xml version="1.0" encoding="utf-8"?>
<!-- This URDF was automatically created by SolidWorks to URDF Exporter! Originally created by Stephen Brawner (brawner@gmail.com) 
     Commit Version: 1.5.1-0-g916b5db  Build Version: 1.5.7152.31018
     For more information, please see http://wiki.ros.org/sw_urdf_exporter -->

<!-- _________________ Begin Robot ___________________ -->

<robot
  name="Ghost">
  

<!-- ___________ Body (Link)  -->
  <link
    name="Body">
    <inertial>
      <origin
        xyz="0.081686 -.1955 0.06534"
        rpy="0 0 0" />
      <mass
        value="0.86083" />
      <inertia
        ixx="0.0025003"
        ixy="-1.6852E-07"
        ixz="-3.7135E-07"
        iyy="0.0034272"
        iyz="-0.00010032"
        izz="0.0015331" />
    </inertial>
    <visual>
      <origin
        xyz="0 0 0"
        rpy="0 0 0" />
      <geometry>
        <mesh
          filename="package://Ghost/meshes/Body.STL" />
      </geometry>
      <material
        name="">
        <color
          rgba="0.75294 0.75294 0.75294 1" />
      </material>
    </visual>
    <collision>
      <origin
        xyz="0 0 0"
        rpy="0 0 0" />
      <geometry>
        <mesh
          filename="package://Ghost/meshes/Body.STL" />
      </geometry>
    </collision>
  </link>
  

<!-- ___________ FR_Motor_2 (Link)  -->


  <link
    name="FR_Motor_2">
    <inertial>
      <origin
        xyz="9.012E-07 0.025811 0.00021934"
        rpy="0 0 0" />
      <mass
        value="0.038306" />
      <inertia
        ixx="8.8892E-06"
        ixy="-8.9901E-11"
        ixz="2.9471E-11"
        iyy="5.0029E-06"
        iyz="-6.1827E-09"
        izz="7.6904E-06" />
    </inertial>
    <visual>
      <origin
        xyz="0 0 0"
        rpy="0 0 0" />
      <geometry>
        <mesh
          filename="package://Ghost/meshes/FR_Motor_2.STL" />
      </geometry>
      <material
        name="">
        <color
          rgba="0.75294 0.75294 0.75294 1" />
      </material>
    </visual>
    <collision>
      <origin
        xyz="0 0 0"
        rpy="0 0 0" />
      <geometry>
        <mesh
          filename="package://Ghost/meshes/FR_Motor_2.STL" />
      </geometry>
    </collision>
  </link>
  

<!-- ___________ FR_Motor_1 (Joint)  -->


  <joint
    name="FR_Motor_1"
    type="continuous">
    <origin
      xyz="0.021553 -0.32985 0.11047"
      rpy="3.1416 1.5708 0" />
    <parent
      link="Body" />
    <child
      link="FR_Motor_2" />
    <axis
      xyz="0 1 0" />
    <limit
      effort = "1.67" lower=" -2.356" upper="2.356" velocity= "6.28"  />  <!-- 1.67 Nm , -135 degrees to +135 degrees , 6.28 rad /s -->
  </joint>
  


<!-- ___________ FR_Upper_Leg (Link)  -->

  <link
    name="FR_Upper_Leg">
    <inertial>
      <origin
        xyz="0.0431132690206234 -0.0364815746629018 -3.16730409638533E-06"
        rpy="0 0 0" />
      <mass
        value="0.0963901848077678" />
      <inertia
        ixx="0.000306808055414335"
        ixy="4.17193030669459E-05"
        ixz="1.01691747269023E-10"
        iyy="8.84229592356097E-05"
        iyz="2.58227797233425E-10"
        izz="0.000290892528790761" />
    </inertial>
    <visual>
      <origin
        xyz="0 0 0"
        rpy="0 0 0" />
      <geometry>
        <mesh
          filename="package://Ghost/meshes/FR_Upper_Leg.STL" />
      </geometry>
      <material
        name="">
        <color
          rgba="0.792156862745098 0.819607843137255 0.933333333333333 1" />
      </material>
    </visual>
    <collision>
      <origin
        xyz="0 0 0"
        rpy="0 0 0" />
      <geometry>
        <mesh
          filename="package://Ghost/meshes/FR_Upper_Leg.STL" />
      </geometry>
    </collision>
  </link>
 
<!-- ___________ FR_Motor_2 (Joint)  -->

  <joint
    name="FR_Motor_2"
    type="continuous">
    <origin
      xyz="0 0.0396 0.025"
      rpy="1.5708 -1.5708 0" />
    <parent
      link="FR_Motor_2" />
    <child
      link="FR_Upper_Leg" />
    <axis
      xyz="1 0 0" />
    <limit
      effort = "1.67" lower=" -1.57" upper="1.57" velocity= "6.28"  />  <!-- 1.67 Nm , -90 degrees to +90 degrees , 6.28 rad /s -->
  </joint>
  

<!-- ___________ FR_Lower_Leg (Link)  -->


  <link
    name="FR_Lower_Leg">
    <inertial>
      <origin
        xyz="-0.0143482972130329 -0.0535566873452038 0.0314220181645453"
        rpy="0 0 0" />
      <mass
        value="0.0246858020584698" />
      <inertia
        ixx="5.85321346620422E-05"
        ixy="3.61624024598202E-06"
        ixz="-2.19618075227486E-06"
        iyy="1.70575774276642E-05"
        iyz="2.53776968704124E-05"
        izz="4.36380655433412E-05" />
    </inertial>
    <visual>
      <origin
        xyz="0 0 0"
        rpy="0 0 0" />
      <geometry>
        <mesh
          filename="package://Ghost/meshes/FR_Lower_Leg.STL" />
      </geometry>
      <material
        name="">
        <color
          rgba="0.792156862745098 0.819607843137255 0.933333333333333 1" />
      </material>
    </visual>
    <collision>
      <origin
        xyz="0 0 0"
        rpy="0 0 0" />
      <geometry>
        <mesh
          filename="package://Ghost/meshes/FR_Lower_Leg.STL" />
      </geometry>
    </collision>
  </link>
 
<!-- ___________ FR_Motor_3 (Joint)  -->



  <joint
    name="FR_Motor_3"
    type="continuous">
    <origin
      xyz="0.031832 -0.175 0"
      rpy="-2.6007 -0.044566 -3.0676" />
    <parent
      link="FR_Upper_Leg" />
    <child
      link="FR_Lower_Leg" />
    <axis
      xyz="0.99627 0.086286 0" />

    <limit
      effort = "1.67" lower=" -2.356" upper="2.356" velocity= "6.28"  />  <!-- 1.67 Nm , -135 degrees to +135 degrees , 6.28 rad /s -->

  </joint>
 
<!-- ___________ FR_Motor_2 (Link)  -->


  <link
    name="FL_Motor_2">
    <inertial>
      <origin
        xyz="9.01197057701086E-07 0.0258106475146923 0.000219339271437385"
        rpy="0 0 0" />
      <mass
        value="0.0383058924829271" />
      <inertia
        ixx="8.8892013763251E-06"
        ixy="-8.99008282971522E-11"
        ixz="2.94712337527189E-11"
        iyy="5.00287526627566E-06"
        iyz="-6.18267002550058E-09"
        izz="7.69036723458957E-06" />
    </inertial>
    <visual>
      <origin
        xyz="0 0 0"
        rpy="0 0 0" />
      <geometry>
        <mesh
          filename="package://Ghost/meshes/FL_Motor_2.STL" />
      </geometry>
      <material
        name="">
        <color
          rgba="0.752941176470588 0.752941176470588 0.752941176470588 1" />
      </material>
    </visual>
    <collision>
      <origin
        xyz="0 0 0"
        rpy="0 0 0" />
      <geometry>
        <mesh
          filename="package://Ghost/meshes/FL_Motor_2.STL" />
      </geometry>
    </collision>
  </link>
 
<!-- ___________ FL_Motor_1 (Joint)  -->



 <joint
    name="FL_Motor_1"
    type="continuous">
    <origin
      xyz="0.14155 -0.32985 0.11047"
      rpy="3.1416 -1.5708 0" />
    <parent
      link="Body" />
    <child
      link="FL_Motor_2" />
    <axis
      xyz="0 1 0" />
    <limit
      effort = "1.67" lower=" -2.356" upper="2.356" velocity= "6.28"  />  <!-- 1.67 Nm , -135 degrees to +135 degrees , 6.28 rad /s -->
  </joint>
 

<!-- ___________ FR_Upper_Leg (Links)  -->

  <link
    name="FL_Upper_Leg">
    <inertial>
      <origin
        xyz="0.0431132690206224 -0.0364815746628984 -3.16730409716248E-06"
        rpy="0 0 0" />
      <mass
        value="0.096390184807772" />
      <inertia
        ixx="0.000306808055414351"
        ixy="4.17193030669484E-05"
        ixz="1.01691747851096E-10"
        iyy="8.84229592356119E-05"
        iyz="2.58227796919532E-10"
        izz="0.000290892528790777" />
    </inertial>
    <visual>
      <origin
        xyz="0 0 0"
        rpy="0 0 0" />
      <geometry>
        <mesh
          filename="package://Ghost/meshes/FL_Upper_Leg.STL" />
      </geometry>
      <material
        name="">
        <color
          rgba="0.792156862745098 0.819607843137255 0.933333333333333 1" />
      </material>
    </visual>
    <collision>
      <origin
        xyz="0 0 0"
        rpy="0 0 0" />
      <geometry>
        <mesh
          filename="package://Ghost/meshes/FL_Upper_Leg.STL" />
      </geometry>
    </collision>
  </link>
  
<!-- ___________ FL_Motor_2 (Joint)  -->

  <joint
    name="FL_Motor_2"
    type="continuous">
    <origin
      xyz="0 0.0396 0.025"
      rpy="-1.5708 -1.5708 0" />
    <parent
      link="FL_Motor_2" />
    <child
      link="FL_Upper_Leg" />
    <axis
      xyz="1 0 0" />
    <limit
      effort = "1.67" lower=" -1.57" upper="1.57" velocity= "6.28"  />  <!-- 1.67 Nm , -90 degrees to +90 degrees , 6.28 rad /s -->
  </joint>
  
<!-- ___________ FL_Lower_Leg (Link)  -->

  <link
    name="FL_Lower_Leg">
    <inertial>
      <origin
        xyz="-0.0143482972130327 -0.0535566873452037 0.0314220181645452"
        rpy="0 0 0" />
      <mass
        value="0.0246858020584693" />
      <inertia
        ixx="5.85321346620381E-05"
        ixy="3.61624024598187E-06"
        ixz="-2.19618075227505E-06"
        iyy="1.70575774276613E-05"
        iyz="2.53776968704141E-05"
        izz="4.363806554334E-05" />
    </inertial>
    <visual>
      <origin
        xyz="0 0 0"
        rpy="0 0 0" />
      <geometry>
        <mesh
          filename="package://Ghost/meshes/FL_Lower_Leg.STL" />
      </geometry>
      <material
        name="">
        <color
          rgba="0.792156862745098 0.819607843137255 0.933333333333333 1" />
      </material>
    </visual>
    <collision>
      <origin
        xyz="0 0 0"
        rpy="0 0 0" />
      <geometry>
        <mesh
          filename="package://Ghost/meshes/FL_Lower_Leg.STL" />
      </geometry>
    </collision>
  </link>
 
 <!-- ___________ FL_Motor_3 (Joint)  -->

  <joint
    name="FL_Motor_3"
    type="continuous">
    <origin
      xyz="0.031832 -0.175 0"
      rpy="-2.6007 -0.044566 -3.0676" />
    <parent
      link="FL_Upper_Leg" />
    <child
      link="FL_Lower_Leg" />
    <axis
      xyz="0.99627 0.086286 0" />
    <limit
      effort = "1.67" lower=" -2.356" upper="2.356" velocity= "6.28"  />  <!-- 1.67 Nm , -135 degrees to +135 degrees , 6.28 rad /s -->
  </joint>
  

<!-- ___________ BR_Motor_2 (Link)  -->

  <link
    name="BR_Motor_2">
    <inertial>
      <origin
        xyz="9.01197057839864E-07 -0.023789352485308 0.000219339271437455"
        rpy="0 0 0" />
      <mass
        value="0.0383058924829273" />
      <inertia
        ixx="8.88920137632513E-06"
        ixy="-8.99008283267111E-11"
        ixz="2.94712337578412E-11"
        iyy="5.00287526627567E-06"
        iyz="-6.18267002551345E-09"
        izz="7.6903672345896E-06" />
    </inertial>
    <visual>
      <origin
        xyz="0 0 0"
        rpy="0 0 0" />
      <geometry>
        <mesh
          filename="package://Ghost/meshes/BR_Motor_2.STL" />
      </geometry>
      <material
        name="">
        <color
          rgba="0.752941176470588 0.752941176470588 0.752941176470588 1" />
      </material>
    </visual>
    <collision>
      <origin
        xyz="0 0 0"
        rpy="0 0 0" />
      <geometry>
        <mesh
          filename="package://Ghost/meshes/BR_Motor_2.STL" />
      </geometry>
    </collision>
  </link>
 
<!-- ___________ FB_Motor_1 (Joint)  -->

  <joint
    name="BR_Motor_1"
    type="continuous">
    <origin
      xyz="0.021553 -0.074252 0.11047"
      rpy="0 -1.5708 0" />
    <parent
      link="Body" />
    <child
      link="BR_Motor_2" />
    <axis
      xyz="0 1 0" />
    <limit
      effort = "1.67" lower=" -2.356" upper="2.356" velocity= "6.28"  />  <!-- 1.67 Nm , -135 degrees to +135 degrees , 6.28 rad /s -->
  </joint>

<!-- ___________ FB_Upper_Leg (Links)  -->

  <link
    name="BR_Upper_Leg">
    <inertial>
      <origin
        xyz="0.0431132690206221 -0.0364815746629001 -3.16730409608001E-06"
        rpy="0 0 0" />
      <mass
        value="0.09639018480777" />
      <inertia
        ixx="0.000306808055414342"
        ixy="4.17193030669474E-05"
        ixz="1.01691747630196E-10"
        iyy="8.8422959235611E-05"
        iyz="2.58227795980033E-10"
        izz="0.000290892528790768" />
    </inertial>
    <visual>
      <origin
        xyz="0 0 0"
        rpy="0 0 0" />
      <geometry>
        <mesh
          filename="package://Ghost/meshes/BR_Upper_Leg.STL" />
      </geometry>
      <material
        name="">
        <color
          rgba="0.792156862745098 0.819607843137255 0.933333333333333 1" />
      </material>
    </visual>
    <collision>
      <origin
        xyz="0 0 0"
        rpy="0 0 0" />
      <geometry>
        <mesh
          filename="package://Ghost/meshes/BR_Upper_Leg.STL" />
      </geometry>
    </collision>
  </link>
 

<!-- ___________ BR_Motor_2 (Joint)  -->

  <joint
    name="BR_Motor_2"
    type="continuous">
    <origin
      xyz="0 -0.01 0.025"
      rpy="-1.5708 -1.5708 0" />
    <parent
      link="BR_Motor_2" />
    <child
      link="BR_Upper_Leg" />
    <axis
      xyz="1 0 0" />
    <limit
      effort = "1.67" lower=" -1.57" upper="1.57" velocity= "6.28"  />  <!-- 1.67 Nm , -90 degrees to +90 degrees , 6.28 rad /s -->
  </joint>

<!-- ___________ BR_Lower_Leg (Link)  -->

  <link
    name="BR_Lower_Leg">
    <inertial>
      <origin
        xyz="-0.0143482972130324 -0.0535566873452041 0.0314220181645452"
        rpy="0 0 0" />
      <mass
        value="0.0246858020584697" />
      <inertia
        ixx="5.85321346620371E-05"
        ixy="3.61624024598189E-06"
        ixz="-2.19618075227503E-06"
        iyy="1.70575774276605E-05"
        iyz="2.53776968704146E-05"
        izz="4.36380655433398E-05" />
    </inertial>
    <visual>
      <origin
        xyz="0 0 0"
        rpy="0 0 0" />
      <geometry>
        <mesh
          filename="package://Ghost/meshes/BR_Lower_Leg.STL" />
      </geometry>
      <material
        name="">
        <color
          rgba="0.792156862745098 0.819607843137255 0.933333333333333 1" />
      </material>
    </visual>
    <collision>
      <origin
        xyz="0 0 0"
        rpy="0 0 0" />
      <geometry>
        <mesh
          filename="package://Ghost/meshes/BR_Lower_Leg.STL" />
      </geometry>
    </collision>
  </link>

<!-- ___________ BR_Motor_3 (Joint)  -->

  <joint
    name="BR_Motor_3"
    type="continuous">
    <origin
      xyz="0.031832 -0.175 0"
      rpy="-2.6007 -0.044566 -3.0676" />
    <parent
      link="BR_Upper_Leg" />
    <child
      link="BR_Lower_Leg" />
    <axis
      xyz="0.99627 0.086286 0" />
    <limit
      effort = "1.67" lower=" -2.356" upper="2.356" velocity= "6.28"  />  <!-- 1.67 Nm , -135 degrees to +135 degrees , 6.28 rad /s -->
  </joint>
  


<!-- ___________ BL_Motor_2 (Link)  -->


  <link
    name="BL_Motor_2">
    <inertial>
      <origin
        xyz="0 0 0"
        rpy="0 0 0" />
      <mass
        value="0" />
      <inertia
        ixx="0"
        ixy="0"
        ixz="0"
        iyy="0"
        iyz="0"
        izz="0" />
    </inertial>
    <visual>
      <origin
        xyz="0 0 0"
        rpy="0 0 0" />
      <geometry>
        <mesh
          filename="package://Ghost/meshes/BL_Motor_2.STL" />
      </geometry>
      <material
        name="">
        <color
          rgba="1 1 1 1" />
      </material>
    </visual>
    <collision>
      <origin
        xyz="0 0 0"
        rpy="0 0 0" />
      <geometry>
        <mesh
          filename="package://Ghost/meshes/BL_Motor_2.STL" />
      </geometry>
    </collision>
  </link>
 
<!-- ___________ BL_Motor_1 (Joint)  -->

  <joint
    name="BL_Motor_1"
    type="continuous">
    <origin
      xyz="0.141552930823638 -0.0742519222843941 0.110467637118315"
      rpy="0 1.5707963267949 0" />
    <parent
      link="Body" />
    <child
      link="BL_Motor_2" />
    <axis
      xyz="0 1 0" />
    <limit
      effort = "1.67" lower=" -2.356" upper="2.356" velocity= "6.28"  />  <!-- 1.67 Nm , -135 degrees to +135 degrees , 6.28 rad /s -->
  </joint>
 

<!-- ___________ BL_Upper_Leg (Link)  -->

  <link
    name="BL_Upper_Leg">
    <inertial>
      <origin
        xyz="0.0431132690206223 -0.0364815746629001 -3.16730409676003E-06"
        rpy="0 0 0" />
      <mass
        value="0.09639018480777" />
      <inertia
        ixx="0.000306808055414343"
        ixy="4.17193030669478E-05"
        ixz="1.01691748114645E-10"
        iyy="8.84229592356104E-05"
        iyz="2.582277956449E-10"
        izz="0.000290892528790769" />
    </inertial>
    <visual>
      <origin
        xyz="0 0 0"
        rpy="0 0 0" />
      <geometry>
        <mesh
          filename="package://Ghost/meshes/BL_Upper_Leg.STL" />
      </geometry>
      <material
        name="">
        <color
          rgba="0.792156862745098 0.819607843137255 0.933333333333333 1" />
      </material>
    </visual>
    <collision>
      <origin
        xyz="0 0 0"
        rpy="0 0 0" />
      <geometry>
        <mesh
          filename="package://Ghost/meshes/BL_Upper_Leg.STL" />
      </geometry>
    </collision>
  </link>
  

<!-- ___________ BL_Motor_2 (Joint)  -->

  <joint
    name="BL_Motor_2"
    type="continuous">
    <origin
      xyz="0 -0.01 0.025"
      rpy="1.5708 -1.5708 0" />
    <parent
      link="BL_Motor_2" />
    <child
      link="BL_Upper_Leg" />
    <axis
      xyz="1 0 0" />
    <limit
      effort = "1.67" lower=" -1.57" upper="1.57" velocity= "6.28"  />  <!-- 1.67 Nm , -90 degrees to +90 degrees , 6.28 rad /s -->
  </joint>
  

<!-- ___________ BL_Lower_Leg (Link)  -->

  <link
    name="BL_Lower_Leg">
    <inertial>
      <origin
        xyz="-0.0143482972130323 -0.0535566873452034 0.0314220181645477"
        rpy="0 0 0" />
      <mass
        value="0.0246858020584695" />
      <inertia
        ixx="5.85321346620351E-05"
        ixy="3.61624024598192E-06"
        ixz="-2.19618075227507E-06"
        iyy="1.70575774276589E-05"
        iyz="2.53776968704157E-05"
        izz="4.36380655433395E-05" />
    </inertial>
    <visual>
      <origin
        xyz="0 0 0"
        rpy="0 0 0" />
      <geometry>
        <mesh
          filename="package://Ghost/meshes/BL_Lower_Leg.STL" />
      </geometry>
      <material
        name="">
        <color
          rgba="0.792156862745098 0.819607843137255 0.933333333333333 1" />
      </material>
    </visual>
    <collision>
      <origin
        xyz="0 0 0"
        rpy="0 0 0" />
      <geometry>
        <mesh
          filename="package://Ghost/meshes/BL_Lower_Leg.STL" />
      </geometry>
    </collision>
  </link>
  
<!-- ___________ BL_Motor_3 (Joint)  -->

  <joint
    name="BL_Motor_3"
    type="continuous">
    <origin
      xyz="0.031832 -0.175 0"
      rpy="-2.6007 -0.044566 -3.0676" />
    <parent
      link="BL_Upper_Leg" />
    <child
      link="BL_Lower_Leg" />
    <axis
      xyz="0.99627 0.086286 0" />
    <limit
      effort = "1.67" lower=" -2.356" upper="2.356" velocity= "6.28"  />  <!-- 1.67 Nm , -135 degrees to +135 degrees , 6.28 rad /s -->
  </joint>
</robot>